Workbook

Sheet Inputs
A1: Montreve: model inputs
A2: Yellow cells are inputs. Every other sheet is formulas on these. Low / base / high are cost-side ranges; for revenue lines they are downside / base / upside.
A4: Key | B4: Input | C4: Low | D4: Base | E4: High | F4: Unit | G4: Source
A5: Program
A6: existing | B6: Financed homes (lots 1, 3, 6, 18, 21, 28, 30) | C6: 7 | D6: 7 | E6: 7 | F6: homes | G6: Will's business plan, Oct 22 2026 p. 2
A7: new_cabins | B7: New cabins on the remaining sale lots | C7: 17 | D7: 17 | E7: 17 | F7: cabins | G7: Site plan: 30 lots - 7 homes - 6 amenity lots
A8: cabin_sf | B8: Cabin conditioned area (684 basement + 880 + 880) | C8: 2444 | D8: 2444 | E8: 2444 | F8: sf | G8: Owner cabin plans
A9: Spent to date (reported, unaudited)
A10: sunk_land | B10: Land | C10: 1500000 | D10: 1500000 | E10: 1500000 | F10: $ | G10: Will's business plan, Oct 22 2026 p. 11 (Oct 20 cost workbook)
A11: sunk_gc | B11: General contractor to date | C11: 4512349.1 | D11: 4512349.1 | E11: 4512349.1 | F11: $ | G11: Will's business plan, Oct 22 2026 p. 11
A12: sunk_soft | B12: Soft costs to date | C12: 639581.6 | D12: 639581.6 | E12: 639581.6 | F12: $ | G12: Will's business plan, Oct 22 2026 p. 11
A13: sunk_int | B13: Interest paid to date | C13: 479850.11 | D13: 479850.11 | E13: 479850.11 | F13: $ | G13: Will's business plan, Oct 22 2026 p. 11
A14: Finish the 7 financed homes
A15: existing_finish | B15: Completion and turnover reserve (all 7) | C15: 300000 | D15: 600000 | E15: 1000000 | F15: $ | G15: Will's business plan, Oct 22 2026 p. 13; GC shows $270,046 left on contract
A16: New cabins (per cabin)
A17: cabin_hard | B17: Vertical construction | C17: 640000 | D17: 710000 | E17: 800000 | F17: $/cabin | G17: Project GC contract $4.78M / 7 = $683k, +4% escalation (base)
A18: cabin_site | B18: Lot work: driveway, septic or sewer tap, power and water service | C18: 40000 | D18: 65000 | E18: 120000 | F18: $/cabin | G18: Allowance; sloped lots, power is the known constraint (fractional plan)
A19: cabin_ffe | B19: Furnishing to rental-ready (sold turnkey) | C19: 40000 | D19: 55000 | E19: 75000 | F19: $/cabin | G19: Allowance
A20: cabin_soft | B20: Soft costs (permits, engineering, builder's risk) | C20: 0.05 | D20: 0.07 | E20: 0.09 | F20: % of hard + lot | G20: Allowance
A21: cabin_cont | B21: Contingency (repeat plan) | C21: 0.05 | D21: 0.08 | E21: 0.12 | F21: % of hard + lot | G21: Allowance
A22: Shared site work (every program)
A23: predev | B23: Survey, topo, geotech, civil, entitlements, HOA documents | C23: 250000 | D23: 450000 | E23: 750000 | F23: $ | G23: Will's business plan, Oct 22 2026 p. 13
A24: infra | B24: Roads to standard, utility mains, power extension, gate and entry, stormwater | C24: 500000 | D24: 900000 | E24: 2000000 | F24: $ | G24: Share of Will's business plan, Oct 22 2026 $0.8-3.0M site line
A25: Resort amenities: full program
A26: pav_sf | B26: Glass wedding pavilion | C26: 6000 | D26: 6000 | E26: 6000 | F26: sf | G26: Will's business plan, Oct 22 2026 p. 6
A27: pav_psf | B27: Pavilion cost | C27: 400 | D27: 550 | E27: 700 | F27: $/sf | G27: Will's business plan, Oct 22 2026 p. 13
A28: din_sf | B28: Dining and catering building | C28: 2500 | D28: 2500 | E28: 2500 | F28: sf | G28: Will's business plan, Oct 22 2026 p. 6
A29: din_psf | B29: Dining cost | C29: 300 | D29: 450 | E29: 600 | F29: $/sf | G29: Will's business plan, Oct 22 2026 p. 13
A30: courts | B30: One tennis and two pickleball courts | C30: 150000 | D30: 220000 | E30: 350000 | F30: $ | G30: Will's business plan, Oct 22 2026 p. 13
A31: trails | B31: Trails and landscape | C31: 60000 | D31: 120000 | E31: 250000 | F31: $ | G31: Will's business plan, Oct 22 2026 p. 13
A32: amen_site | B32: Event parking and amenity site work | C32: 300000 | D32: 600000 | E32: 1000000 | F32: $ | G32: Balance of Will's business plan, Oct 22 2026 site line
A33: amen_ffe | B33: Amenity furniture and equipment | C33: 200000 | D33: 300000 | E33: 500000 | F33: $ | G33: Will's business plan, Oct 22 2026 p. 13 (cabins excluded)
A34: preopen | B34: Preopening and working capital | C34: 250000 | D34: 400000 | E34: 600000 | F34: $ | G34: Will's business plan, Oct 22 2026 p. 13
A35: Resort amenities: lean program
A36: lpav_sf | B36: Smaller pavilion | C36: 3000 | D36: 3000 | E36: 3000 | F36: sf | G36: Will's business plan, Oct 22 2026 p. 17
A37: lpav_psf | B37: Smaller pavilion cost | C37: 380 | D37: 500 | E37: 620 | F37: $/sf | G37: Will's business plan, Oct 22 2026 p. 17
A38: lsvc_sf | B38: Caterer service kitchen | C38: 800 | D38: 800 | E38: 800 | F38: sf | G38: Will's business plan, Oct 22 2026 p. 17
A39: lsvc_psf | B39: Service kitchen cost | C39: 300 | D39: 400 | E39: 520 | F39: $/sf | G39: Will's business plan, Oct 22 2026 p. 17
A40: lamen_site | B40: Event parking and site work (lean) | C40: 200000 | D40: 400000 | E40: 700000 | F40: $ | G40: Allowance
A41: lamen_ffe | B41: Amenity furniture (lean) | C41: 100000 | D41: 150000 | E41: 250000 | F41: $ | G41: Allowance
...

Sheet Budget
A1: Development budget and break-even
A2: All 24 cabins for sale; the amenity line changes with the program. Columns: low / base / high cost case.
A4: Line | B4: Low | C4: Base | D4: High | E4: Note
A5: Cabins for sale | B5: =Inputs!$C$6+Inputs!$C$7 | C5: =Inputs!$D$6+Inputs!$D$7 | D5: =Inputs!$E$6+Inputs!$E$7
A6: Spent to date (land, GC, soft, interest; reported) | B6: =Inputs!$C$10+Inputs!$C$11+Inputs!$C$12+Inputs!$C$13 | C6: =Inputs!$D$10+Inputs!$D$11+Inputs!$D$12+Inputs!$D$13 | D6: =Inputs!$E$10+Inputs!$E$11+Inputs!$E$12+Inputs!$E$13 | E6: Oct 20 workbook; not yet reconciled to the ledger
A7: Finish the 7 financed homes | B7: =Inputs!$C$15 | C7: =Inputs!$D$15 | D7: =Inputs!$E$15
A8: One new cabin, all in | B8: =(Inputs!$C$17+Inputs!$C$18)*(1+Inputs!$C$20+Inputs!$C$21)+Inputs!$C$19 | C8: =(Inputs!$D$17+Inputs!$D$18)*(1+Inputs!$D$20+Inputs!$D$21)+Inputs!$D$19 | D8: =(Inputs!$E$17+Inputs!$E$18)*(1+Inputs!$E$20+Inputs!$E$21)+Inputs!$E$19 | E8: Hard + lot work, soft costs, contingency, furniture
A9: per sf | B9: =B8/Inputs!$C$8 | C9: =C8/Inputs!$D$8 | D9: =D8/Inputs!$E$8
A10: New cabins (17) | B10: =B8*Inputs!$C$7 | C10: =C8*Inputs!$D$7 | D10: =D8*Inputs!$E$7
A11: Shared site work and predevelopment | B11: =Inputs!$C$23+Inputs!$C$24 | C11: =Inputs!$D$23+Inputs!$D$24 | D11: =Inputs!$E$23+Inputs!$E$24
A12: Resort amenities: lean program | B12: =(Inputs!$C$36*Inputs!$C$37+Inputs!$C$38*Inputs!$C$39+Inputs!$C$30+Inputs!$C$31+Inputs!$C$40+Inputs!$C$41)*(1+Inputs!$C$43)+Inputs!$C$42 | C12: =(Inputs!$D$36*Inputs!$D$37+Inputs!$D$38*Inputs!$D$39+Inputs!$D$30+Inputs!$D$31+Inputs!$D$40+Inputs!$D$41)*(1+Inputs!$D$43)+Inputs!$D$42 | D12: =(Inputs!$E$36*Inputs!$E$37+Inputs!$E$38*Inputs!$E$39+Inputs!$E$30+Inputs!$E$31+Inputs!$E$40+Inputs!$E$41)*(1+Inputs!$E$43)+Inputs!$E$42 | E12: 3,000 sf pavilion, 800 sf service kitchen, courts, trails
A13: Resort amenities: full program | B13: =(Inputs!$C$26*Inputs!$C$27+Inputs!$C$28*Inputs!$C$29+Inputs!$C$30+Inputs!$C$31+Inputs!$C$32+Inputs!$C$33)*(1+Inputs!$C$43)+Inputs!$C$34 | C13: =(Inputs!$D$26*Inputs!$D$27+Inputs!$D$28*Inputs!$D$29+Inputs!$D$30+Inputs!$D$31+Inputs!$D$32+Inputs!$D$33)*(1+Inputs!$D$43)+Inputs!$D$34 | D13: =(Inputs!$E$26*Inputs!$E$27+Inputs!$E$28*Inputs!$E$29+Inputs!$E$30+Inputs!$E$31+Inputs!$E$32+Inputs!$E$33)*(1+Inputs!$E$43)+Inputs!$E$34 | E13: 6,000 sf pavilion, 2,500 sf dining, courts, trails
A14: Carry on new spend (share of it) | B14: =Inputs!$C$45*Inputs!$C$46*Inputs!$C$47/12+Inputs!$C$48 | C14: =Inputs!$D$45*Inputs!$D$46*Inputs!$D$47/12+Inputs!$D$48 | D14: =Inputs!$E$45*Inputs!$E$46*Inputs!$E$47/12+Inputs!$E$48 | E14: Interest on the average balance + loan fees
A15: Carry on the existing loans until the homes sell | B15: =Inputs!$C$49*Inputs!$C$45*Inputs!$C$50/12+Inputs!$C$51*Inputs!$C$50/3 | C15: =Inputs!$D$49*Inputs!$D$45*Inputs!$D$50/12+Inputs!$D$51*Inputs!$D$50/3 | D15: =Inputs!$E$49*Inputs!$E$45*Inputs!$E$50/12+Inputs!$E$51*Inputs!$E$50/3
A16: Marketing and unsold-inventory holding | B16: =Inputs!$C$54+Inputs!$C$55 | C16: =Inputs!$D$54+Inputs!$D$55 | D16: =Inputs!$E$54+Inputs!$E$55
A17: Selling cost (commission + closing) | B17: =Inputs!$C$52+Inputs!$C$53 | C17: =Inputs!$D$52+Inputs!$D$53 | D17: =Inputs!$E$52+Inputs!$E$53
A19: Program A: cabins only (amenities deferred)
A20: New spend | B20: =B7+B10+B11+0 | C20: =C7+C10+C11+0 | D20: =D7+D10+D11+0
A21: Total cost (to date + new + financing + selling fixed) | B21: =B6+B20*(1+B14)+B15+B16 | C21: =C6+C20*(1+C14)+C15+C16 | D21: =D6+D20*(1+D14)+D15+D16
A22: Break-even price per cabin | B22: =B21/(B5*(1-B17)) | C22: =C21/(C5*(1-C17)) | D22: =D21/(D5*(1-D17))
A23: Price for the margin target | B23: =B21*(1+Inputs!$C$58)/(B5*(1-B17)) | C23: =C21*(1+Inputs!$D$58)/(C5*(1-C17)) | D23: =D21*(1+Inputs!$E$58)/(D5*(1-D17))
A24: Profit if every cabin sells at the tested price | B24: =B5*Inputs!$C$57*(1-B17)-B21 | C24: =C5*Inputs!$D$57*(1-C17)-C21 | D24: =D5*Inputs!$E$57*(1-D17)-D21
A25: Break-even vs listed comparable cabins | B25: =B22/Inputs!$C$59-1 | C25: =C22/Inputs!$D$59-1 | D25: =D22/Inputs!$E$59-1
A27: Program B: cabins + lean resort
A28: New spend | B28: =B7+B10+B11+B12 | C28: =C7+C10+C11+C12 | D28: =D7+D10+D11+D12
A29: Total cost (to date + new + financing + selling fixed) | B29: =B6+B28*(1+B14)+B15+B16 | C29: =C6+C28*(1+C14)+C15+C16 | D29: =D6+D28*(1+D14)+D15+D16
A30: Break-even price per cabin | B30: =B29/(B5*(1-B17)) | C30: =C29/(C5*(1-C17)) | D30: =D29/(D5*(1-D17))
A31: Price for the margin target | B31: =B29*(1+Inputs!$C$58)/(B5*(1-B17)) | C31: =C29*(1+Inputs!$D$58)/(C5*(1-C17)) | D31: =D29*(1+Inputs!$E$58)/(D5*(1-D17))
A32: Profit if every cabin sells at the tested price | B32: =B5*Inputs!$C$57*(1-B17)-B29 | C32: =C5*Inputs!$D$57*(1-C17)-C29 | D32: =D5*Inputs!$E$57*(1-D17)-D29
A33: Break-even vs listed comparable cabins | B33: =B30/Inputs!$C$59-1 | C33: =C30/Inputs!$D$59-1 | D33: =D30/Inputs!$E$59-1
A35: Program C: cabins + full resort
A36: New spend | B36: =B7+B10+B11+B13 | C36: =C7+C10+C11+C13 | D36: =D7+D10+D11+D13
A37: Total cost (to date + new + financing + selling fixed) | B37: =B6+B36*(1+B14)+B15+B16 | C37: =C6+C36*(1+C14)+C15+C16 | D37: =D6+D36*(1+D14)+D15+D16
A38: Break-even price per cabin | B38: =B37/(B5*(1-B17)) | C38: =C37/(C5*(1-C17)) | D38: =D37/(D5*(1-D17))
A39: Price for the margin target | B39: =B37*(1+Inputs!$C$58)/(B5*(1-B17)) | C39: =C37*(1+Inputs!$D$58)/(C5*(1-C17)) | D39: =D37*(1+Inputs!$E$58)/(D5*(1-D17))
A40: Profit if every cabin sells at the tested price | B40: =B5*Inputs!$C$57*(1-B17)-B37 | C40: =C5*Inputs!$D$57*(1-C17)-C37 | D40: =D5*Inputs!$E$57*(1-D17)-D37
A41: Break-even vs listed comparable cabins | B41: =B38/Inputs!$C$59-1 | C41: =C38/Inputs!$D$59-1 | D41: =D38/Inputs!$E$59-1
A43: Amenity budget a sale at the tested price can carry (break-even) | B43: =(B5*Inputs!$C$57*(1-B17)-B15-B16)/(1+B14)-B6-B7-B10-B11 | C43: =(C5*Inputs!$D$57*(1-C17)-C15-C16)/(1+C14)-C6-C7-C10-C11 | D43: =(D5*Inputs!$E$57*(1-D17)-D15-D16)/(1+D14)-D6-D7-D10-D11 | E43: Negative: the tested price does not cover the cabins and site work before any amenity

Sheet Resort operations
A1: Resort operations: stabilized year (full program)
A2: Venue, rental management and club dues. Catering is outsourced: food spend is not resort revenue. Downside / base / upside.
A4: Line | B4: Downside | C4: Base | D4: Upside | E4: How
A5: Venue fees (weddings + retreats) | B5: =Inputs!$C$61*Inputs!$C$62+Inputs!$C$63*Inputs!$C$64 | C5: =Inputs!$D$61*Inputs!$D$62+Inputs!$D$63*Inputs!$D$64 | D5: =Inputs!$E$61*Inputs!$E$62+Inputs!$E$63*Inputs!$E$64
A6: Kitchen use, bar and rentals | B6: =(Inputs!$C$61+Inputs!$C$63)*Inputs!$C$65 | C6: =(Inputs!$D$61+Inputs!$D$63)*Inputs!$D$65 | D6: =(Inputs!$E$61+Inputs!$E$63)*Inputs!$E$65
A7: Other property revenue | B7: =Inputs!$C$66 | C7: =Inputs!$D$66 | D7: =Inputs!$E$66
A8: Rental management fees | B8: =(Inputs!$C$6+Inputs!$C$7)*Inputs!$C$67*Inputs!$C$68*Inputs!$C$69 | C8: =(Inputs!$D$6+Inputs!$D$7)*Inputs!$D$67*Inputs!$D$68*Inputs!$D$69 | D8: =(Inputs!$E$6+Inputs!$E$7)*Inputs!$E$67*Inputs!$E$68*Inputs!$E$69 | E8: Cabins in program x gross rent x fee
A9: Owner club dues | B9: =(Inputs!$C$6+Inputs!$C$7)*Inputs!$C$71*12 | C9: =(Inputs!$D$6+Inputs!$D$7)*Inputs!$D$71*12 | D9: =(Inputs!$E$6+Inputs!$E$7)*Inputs!$E$71*12
A10: Revenue | B10: =SUM(B5:B9) | C10: =SUM(C5:C9) | D10: =SUM(D5:D9)
A11: Event variable cost | B11: =(B5+B6)*Inputs!$C$72 | C11: =(C5+C6)*Inputs!$D$72 | D11: =(D5+D6)*Inputs!$E$72
A12: Other variable cost | B12: =B7*Inputs!$C$73 | C12: =C7*Inputs!$D$73 | D12: =D7*Inputs!$E$73
A13: Rental program direct cost | B13: =B8*Inputs!$C$70 | C13: =C8*Inputs!$D$70 | D13: =D8*Inputs!$E$70
A14: Fixed overhead | B14: =Inputs!$C$74 | C14: =Inputs!$D$74 | D14: =Inputs!$E$74
A15: Replacement reserve | B15: =B10*Inputs!$C$75 | C15: =C10*Inputs!$D$75 | D15: =D10*Inputs!$E$75
A16: Operating cost | B16: =SUM(B11:B15) | C16: =SUM(C11:C15) | D16: =SUM(D11:D15)
A17: Net operating income | B17: =B10-B16 | C17: =C10-C16 | D17: =D10-D16
A18: Value of the resort business at the cap rate | B18: =MAX(0,B17)/Inputs!$C$76 | C18: =MAX(0,C17)/Inputs!$D$76 | D18: =MAX(0,D17)/Inputs!$E$76

Sheet Owner economics
A1: What a cabin owner can expect: one cabin, a year in the rental program
A2: Before any mortgage and income tax. Illustration for discussion, not a promise of income.
A4: Line | B4: Downside | C4: Base | D4: Upside
A5: Gross rent | B5: =Inputs!$C$68 | C5: =Inputs!$D$68 | D5: =Inputs!$E$68
A6: Management fee | B6: =-Inputs!$C$68*Inputs!$D$69 | C6: =-Inputs!$D$68*Inputs!$D$69 | D6: =-Inputs!$E$68*Inputs!$D$69
A7: Utilities, internet, pool service | B7: =-Inputs!$D$78 | C7: =-Inputs!$D$78 | D7: =-Inputs!$D$78
A8: Maintenance and supplies | B8: =-Inputs!$D$79 | C8: =-Inputs!$D$79 | D8: =-Inputs!$D$79
A9: Insurance | B9: =-Inputs!$D$80 | C9: =-Inputs!$D$80 | D9: =-Inputs!$D$80
A10: Property tax | B10: =-Inputs!$D$57*Inputs!$D$81 | C10: =-Inputs!$D$57*Inputs!$D$81 | D10: =-Inputs!$D$57*Inputs!$D$81
A11: Club dues | B11: =-Inputs!$D$71*12 | C11: =-Inputs!$D$71*12 | D11: =-Inputs!$D$71*12
A12: Net to owner | B12: =SUM(B5:B11) | C12: =SUM(C5:C11) | D12: =SUM(D5:D11)
A13: Cash yield on the purchase price | B13: =B12/Inputs!$C$57 | C13: =C12/Inputs!$D$57 | D13: =D12/Inputs!$E$57
A15: Only the gross rent changes across the columns; the fee, costs and dues are the base inputs.

Sheet Price sensitivity
A1: Profit at each sale price (base costs)
A3: Price per cabin | B3: A: cabins only | C3: B: lean resort | D3: C: full resort
A4: 1000000 | B4: =Budget!$C$5*$A4*(1-Budget!$C$17)-Budget!$C$21 | C4: =Budget!$C$5*$A4*(1-Budget!$C$17)-Budget!$C$29 | D4: =Budget!$C$5*$A4*(1-Budget!$C$17)-Budget!$C$37
A5: 1050000 | B5: =Budget!$C$5*$A5*(1-Budget!$C$17)-Budget!$C$21 | C5: =Budget!$C$5*$A5*(1-Budget!$C$17)-Budget!$C$29 | D5: =Budget!$C$5*$A5*(1-Budget!$C$17)-Budget!$C$37
A6: 1100000 | B6: =Budget!$C$5*$A6*(1-Budget!$C$17)-Budget!$C$21 | C6: =Budget!$C$5*$A6*(1-Budget!$C$17)-Budget!$C$29 | D6: =Budget!$C$5*$A6*(1-Budget!$C$17)-Budget!$C$37
A7: 1150000 | B7: =Budget!$C$5*$A7*(1-Budget!$C$17)-Budget!$C$21 | C7: =Budget!$C$5*$A7*(1-Budget!$C$17)-Budget!$C$29 | D7: =Budget!$C$5*$A7*(1-Budget!$C$17)-Budget!$C$37
A8: 1200000 | B8: =Budget!$C$5*$A8*(1-Budget!$C$17)-Budget!$C$21 | C8: =Budget!$C$5*$A8*(1-Budget!$C$17)-Budget!$C$29 | D8: =Budget!$C$5*$A8*(1-Budget!$C$17)-Budget!$C$37
A9: 1250000 | B9: =Budget!$C$5*$A9*(1-Budget!$C$17)-Budget!$C$21 | C9: =Budget!$C$5*$A9*(1-Budget!$C$17)-Budget!$C$29 | D9: =Budget!$C$5*$A9*(1-Budget!$C$17)-Budget!$C$37
A10: 1300000 | B10: =Budget!$C$5*$A10*(1-Budget!$C$17)-Budget!$C$21 | C10: =Budget!$C$5*$A10*(1-Budget!$C$17)-Budget!$C$29 | D10: =Budget!$C$5*$A10*(1-Budget!$C$17)-Budget!$C$37
A11: 1350000 | B11: =Budget!$C$5*$A11*(1-Budget!$C$17)-Budget!$C$21 | C11: =Budget!$C$5*$A11*(1-Budget!$C$17)-Budget!$C$29 | D11: =Budget!$C$5*$A11*(1-Budget!$C$17)-Budget!$C$37
A12: 1400000 | B12: =Budget!$C$5*$A12*(1-Budget!$C$17)-Budget!$C$21 | C12: =Budget!$C$5*$A12*(1-Budget!$C$17)-Budget!$C$29 | D12: =Budget!$C$5*$A12*(1-Budget!$C$17)-Budget!$C$37
A13: 1450000 | B13: =Budget!$C$5*$A13*(1-Budget!$C$17)-Budget!$C$21 | C13: =Budget!$C$5*$A13*(1-Budget!$C$17)-Budget!$C$29 | D13: =Budget!$C$5*$A13*(1-Budget!$C$17)-Budget!$C$37
A14: 1500000 | B14: =Budget!$C$5*$A14*(1-Budget!$C$17)-Budget!$C$21 | C14: =Budget!$C$5*$A14*(1-Budget!$C$17)-Budget!$C$29 | D14: =Budget!$C$5*$A14*(1-Budget!$C$17)-Budget!$C$37
A15: 1550000 | B15: =Budget!$C$5*$A15*(1-Budget!$C$17)-Budget!$C$21 | C15: =Budget!$C$5*$A15*(1-Budget!$C$17)-Budget!$C$29 | D15: =Budget!$C$5*$A15*(1-Budget!$C$17)-Budget!$C$37
... A18: 1700000 | B18: =Budget!$C$5*$A18*(1-Budget!$C$17)-Budget!$C$21 | C18: =Budget!$C$5*$A18*(1-Budget!$C$17)-Budget!$C$29 | D18: =Budget!$C$5*$A18*(1-Budget!$C$17)-Budget!$C$37

Sheet Cash flow
A1: Quarterly cash flow, base costs, at the tested price
A3: Program (A, B or C): | B3: C
A4: Timing rows (yellow) are the share of each cost spent, or cabins sold, in each quarter. Existing loans are repaid from the first home sales.
A6: Line | B6: 2027 Q1 | C6: 2027 Q2 | D6: 2027 Q3 | E6: 2027 Q4 | F6: 2028 Q1 | G6: 2028 Q2 | H6: 2028 Q3 | I6: 2028 Q4 | J6: 2029 Q1 | K6: 2029 Q2 | L6: 2029 Q3 | M6: 2029 Q4 | N6: 2030 Q1 | O6: 2030 Q2 | P6: 2030 Q3 | Q6: 2030 Q4 | R6: Total
A7: Finish 7 homes (share) | B7: 0.5 | C7: 0.5 | D7: 0 | E7: 0 | F7: 0 | G7: 0 | H7: 0 | I7: 0 | J7: 0 | K7: 0 | L7: 0 | M7: 0 | N7: 0 | O7: 0 | P7: 0 | Q7: 0 | R7: =SUM(B7:Q7)
A8: Shared site work (share) | B8: 0.2 | C8: 0.3 | D8: 0.3 | E8: 0.2 | F8: 0 | G8: 0 | H8: 0 | I8: 0 | J8: 0 | K8: 0 | L8: 0 | M8: 0 | N8: 0 | O8: 0 | P8: 0 | Q8: 0 | R8: =SUM(B8:Q8)
A9: Amenities (share) | B9: 0 | C9: 0.1 | D9: 0.2 | E9: 0.25 | F9: 0.25 | G9: 0.2 | H9: 0 | I9: 0 | J9: 0 | K9: 0 | L9: 0 | M9: 0 | N9: 0 | O9: 0 | P9: 0 | Q9: 0 | R9: =SUM(B9:Q9)
A10: New cabins (share) | B10: 0 | C10: 0.06 | D10: 0.12 | E10: 0.12 | F10: 0.12 | G10: 0.12 | H10: 0.12 | I10: 0.12 | J10: 0.12 | K10: 0.1 | L10: 0 | M10: 0 | N10: 0 | O10: 0 | P10: 0 | Q10: 0 | R10: =SUM(B10:Q10)
A11: Financed homes sold (count) | B11: 2 | C11: 3 | D11: 2 | E11: 0 | F11: 0 | G11: 0 | H11: 0 | I11: 0 | J11: 0 | K11: 0 | L11: 0 | M11: 0 | N11: 0 | O11: 0 | P11: 0 | Q11: 0 | R11: =SUM(B11:Q11)
A12: New cabins sold (count) | B12: 0 | C12: 0 | D12: 0 | E12: 1 | F12: 2 | G12: 2 | H12: 2 | I12: 2 | J12: 2 | K12: 2 | L12: 2 | M12: 2 | N12: 0 | O12: 0 | P12: 0 | Q12: 0 | R12: =SUM(B12:Q12)
A14: Development spend | B14: =-(B7*Budget!$C$7+B8*Budget!$C$11+B9*IF($B$3="A",0,IF($B$3="B",Budget!$C$12,Budget!$C$13))+B10*Budget!$C$10) | C14: =-(C7*Budget!$C$7+C8*Budget!$C$11+C9*IF($B$3="A",0,IF($B$3="B",Budget!$C$12,Budget!$C$13))+C10*Budget!$C$10) | D14: =-(D7*Budget!$C$7+D8*Budget!$C$11+D9*IF($B$3="A",0,IF($B$3="B",Budget!$C$12,Budget!$C$13))+D10*Budget!$C$10) | E14: =-(E7*Budget!$C$7+E8*Budget!$C$11+E9*IF($B$3="A",0,IF($B$3="B",Budget!$C$12,Budget!$C$13))+E10*Budget!$C$10) | F14: =-(F7*Budget!$C$7+F8*Budget!$C$11+F9*IF($B$3="A",0,IF($B$3="B",Budget!$C$12,Budget!$C$13))+F10*Budget!$C$10) | G14: =-(G7*Budget!$C$7+G8*Budget!$C$11+G9*IF($B$3="A",0,IF($B$3="B",Budget!$C$12,Budget!$C$13))+G10*Budget!$C$10) | H14: =-(H7*Budget!$C$7+H8*Budget!$C$11+H9*IF($B$3="A",0,IF($B$3="B",Budget!$C$12,Budget!$C$13))+H10*Budget!$C$10) | I14: =-(I7*Budget!$C$7+I8*Budget!$C$11+I9*IF($B$3="A",0,IF($B$3="B",Budget!$C$12,Budget!$C$13))+I10*Budget!$C$10) | ... Q14: =-(Q7*Budget!$C$7+Q8*Budget!$C$11+Q9*IF($B$3="A",0,IF($B$3="B",Budget!$C$12,Budget!$C$13))+Q10*Budget!$C$10) | R14: =SUM(B14:Q14)
A15: Financing (spread with spend) | B15: =B14*Budget!$C$14 | C15: =C14*Budget!$C$14 | D15: =D14*Budget!$C$14 | E15: =E14*Budget!$C$14 | F15: =F14*Budget!$C$14 | G15: =G14*Budget!$C$14 | H15: =H14*Budget!$C$14 | I15: =I14*Budget!$C$14 | ... Q15: =Q14*Budget!$C$14 | R15: =SUM(B15:Q15)
A16: Carry on existing loans (while open) | B16: =-IF(SUM($B11:B11)-B11<Inputs!$D$6,Budget!$C$15/ROUNDUP(Inputs!$D$50/3,0),0) | C16: =-IF(SUM($B11:C11)-C11<Inputs!$D$6,Budget!$C$15/ROUNDUP(Inputs!$D$50/3,0),0) | D16: =-IF(SUM($B11:D11)-D11<Inputs!$D$6,Budget!$C$15/ROUNDUP(Inputs!$D$50/3,0),0) | E16: =-IF(SUM($B11:E11)-E11<Inputs!$D$6,Budget!$C$15/ROUNDUP(Inputs!$D$50/3,0),0) | F16: =-IF(SUM($B11:F11)-F11<Inputs!$D$6,Budget!$C$15/ROUNDUP(Inputs!$D$50/3,0),0) | G16: =-IF(SUM($B11:G11)-G11<Inputs!$D$6,Budget!$C$15/ROUNDUP(Inputs!$D$50/3,0),0) | H16: =-IF(SUM($B11:H11)-H11<Inputs!$D$6,Budget!$C$15/ROUNDUP(Inputs!$D$50/3,0),0) | I16: =-IF(SUM($B11:I11)-I11<Inputs!$D$6,Budget!$C$15/ROUNDUP(Inputs!$D$50/3,0),0) | ... Q16: =-IF(SUM($B11:Q11)-Q11<Inputs!$D$6,Budget!$C$15/ROUNDUP(Inputs!$D$50/3,0),0) | R16: =SUM(B16:Q16)
A17: Marketing and holding | B17: =-Budget!$C$16/16 | C17: =-Budget!$C$16/16 | D17: =-Budget!$C$16/16 | E17: =-Budget!$C$16/16 | F17: =-Budget!$C$16/16 | G17: =-Budget!$C$16/16 | H17: =-Budget!$C$16/16 | I17: =-Budget!$C$16/16 | ... Q17: =-Budget!$C$16/16 | R17: =SUM(B17:Q17)
A18: Repay existing loans (as each financed home sells) | B18: =-B11/Inputs!$D$6*Inputs!$D$49 | C18: =-C11/Inputs!$D$6*Inputs!$D$49 | D18: =-D11/Inputs!$D$6*Inputs!$D$49 | E18: =-E11/Inputs!$D$6*Inputs!$D$49 | F18: =-F11/Inputs!$D$6*Inputs!$D$49 | G18: =-G11/Inputs!$D$6*Inputs!$D$49 | H18: =-H11/Inputs!$D$6*Inputs!$D$49 | I18: =-I11/Inputs!$D$6*Inputs!$D$49 | ... Q18: =-Q11/Inputs!$D$6*Inputs!$D$49 | R18: =SUM(B18:Q18)
A19: Net sales proceeds | B19: =(B11+B12)*Inputs!$D$57*(1-Budget!$C$17) | C19: =(C11+C12)*Inputs!$D$57*(1-Budget!$C$17) | D19: =(D11+D12)*Inputs!$D$57*(1-Budget!$C$17) | E19: =(E11+E12)*Inputs!$D$57*(1-Budget!$C$17) | F19: =(F11+F12)*Inputs!$D$57*(1-Budget!$C$17) | G19: =(G11+G12)*Inputs!$D$57*(1-Budget!$C$17) | H19: =(H11+H12)*Inputs!$D$57*(1-Budget!$C$17) | I19: =(I11+I12)*Inputs!$D$57*(1-Budget!$C$17) | ... Q19: =(Q11+Q12)*Inputs!$D$57*(1-Budget!$C$17) | R19: =SUM(B19:Q19)
A20: Net cash flow | B20: =SUM(B14:B19) | C20: =SUM(C14:C19) | D20: =SUM(D14:D19) | E20: =SUM(E14:E19) | F20: =SUM(F14:F19) | G20: =SUM(G14:G19) | H20: =SUM(H14:H19) | I20: =SUM(I14:I19) | ... Q20: =SUM(Q14:Q19) | R20: =SUM(B20:Q20)
A21: Cumulative | B21: =B20 | C21: =B21+C20 | D21: =C21+D20 | E21: =D21+E20 | F21: =E21+F20 | G21: =F21+G20 | H21: =G21+H20 | I21: =H21+I20 | J21: =I21+J20 | ... Q21: =P21+Q20
A23: Peak cash need (most negative cumulative) | B23: =MIN(B21:Q21)
A24: Spent to date is not in this sheet (already spent). Peak cash need is what equity and construction loans must cover together.
